Workbook
Name Slicer_Representative: #N/A

Sheet Dashboard
T17: =pivots!B59 -> R01 | U17: =pivots!C59 -> R02 | V17: =pivots!D59 -> R03 | W17: =pivots!E59 -> R04 | X17: =pivots!F59 -> R05 | Y17: Total
S18: =IF(pivots!A60<>0,pivots!A60,"") -> Cincinnati | T18: =IF(pivots!B60<>0,pivots!B60,"") | U18: =IF(pivots!C60<>0,pivots!C60,"") | V18: =IF(pivots!D60<>0,pivots!D60,"") | W18: =IF(pivots!E60<>0,pivots!E60,"") | X18: =IF(pivots!F60<>0,pivots!F60,"") | Y18: =IF(pivots!G60<>0,pivots!G60,"")
S19: =IF(pivots!A61<>0,pivots!A61,"") -> C0003 | T19: =IF(pivots!B61<>0,pivots!B61,"") -> 891 | U19: =IF(pivots!C61<>0,pivots!C61,"") -> 1332 | V19: =IF(pivots!D61<>0,pivots!D61,"") -> 1282 | W19: =IF(pivots!E61<>0,pivots!E61,"") -> 739 | X19: =IF(pivots!F61<>0,pivots!F61,"") -> 560 | Y19: =IF(pivots!G61<>0,pivots!G61,"") -> 4804
S20: =IF(pivots!A62<>0,pivots!A62,"") -> C0004 | T20: =IF(pivots!B62<>0,pivots!B62,"") -> 1991 | U20: =IF(pivots!C62<>0,pivots!C62,"") -> 1886 | V20: =IF(pivots!D62<>0,pivots!D62,"") -> 1206 | W20: =IF(pivots!E62<>0,pivots!E62,"") -> 884 | X20: =IF(pivots!F62<>0,pivots!F62,"") -> 1722 | Y20: =IF(pivots!G62<>0,pivots!G62,"") -> 7689
S21: =IF(pivots!A63<>0,pivots!A63,"") -> C0011 | T21: =IF(pivots!B63<>0,pivots!B63,"") -> 1163 | U21: =IF(pivots!C63<>0,pivots!C63,"") -> 1180 | V21: =IF(pivots!D63<>0,pivots!D63,"") -> 1616 | W21: =IF(pivots!E63<>0,pivots!E63,"") -> 1043 | X21: =IF(pivots!F63<>0,pivots!F63,"") -> 1747 | Y21: =IF(pivots!G63<>0,pivots!G63,"") -> 6749
S22: =IF(pivots!A64<>0,pivots!A64,"") -> C0012 | T22: =IF(pivots!B64<>0,pivots!B64,"") -> 1438 | U22: =IF(pivots!C64<>0,pivots!C64,"") -> 1616 | V22: =IF(pivots!D64<>0,pivots!D64,"") -> 866 | W22: =IF(pivots!E64<>0,pivots!E64,"") -> 829 | X22: =IF(pivots!F64<>0,pivots!F64,"") -> 2070 | Y22: =IF(pivots!G64<>0,pivots!G64,"") -> 6819
S23: =IF(pivots!A65<>0,pivots!A65,"") -> Cleveland | T23: =IF(pivots!B65<>0,pivots!B65,"") | U23: =IF(pivots!C65<>0,pivots!C65,"") | V23: =IF(pivots!D65<>0,pivots!D65,"") | W23: =IF(pivots!E65<>0,pivots!E65,"") | X23: =IF(pivots!F65<>0,pivots!F65,"") | Y23: =IF(pivots!G65<>0,pivots!G65,"")
S24: =IF(pivots!A66<>0,pivots!A66,"") -> C0002 | T24: =IF(pivots!B66<>0,pivots!B66,"") -> 1233 | U24: =IF(pivots!C66<>0,pivots!C66,"") -> 223 | V24: =IF(pivots!D66<>0,pivots!D66,"") -> 1680 | W24: =IF(pivots!E66<>0,pivots!E66,"") -> 990 | X24: =IF(pivots!F66<>0,pivots!F66,"") -> 1508 | Y24: =IF(pivots!G66<>0,pivots!G66,"") -> 5634
S25: =IF(pivots!A67<>0,pivots!A67,"") -> C0007 | T25: =IF(pivots!B67<>0,pivots!B67,"") -> 1598 | U25: =IF(pivots!C67<>0,pivots!C67,"") -> 1907 | V25: =IF(pivots!D67<>0,pivots!D67,"") -> 869 | W25: =IF(pivots!E67<>0,pivots!E67,"") -> 1426 | X25: =IF(pivots!F67<>0,pivots!F67,"") -> 1416 | Y25: =IF(pivots!G67<>0,pivots!G67,"") -> 7216
S26: =IF(pivots!A68<>0,pivots!A68,"") -> C0008 | T26: =IF(pivots!B68<>0,pivots!B68,"") -> 900 | U26: =IF(pivots!C68<>0,pivots!C68,"") -> 1016 | V26: =IF(pivots!D68<>0,pivots!D68,"") -> 960 | W26: =IF(pivots!E68<>0,pivots!E68,"") -> 940 | X26: =IF(pivots!F68<>0,pivots!F68,"") -> 1193 | Y26: =IF(pivots!G68<>0,pivots!G68,"") -> 5009
S27: =IF(pivots!A69<>0,pivots!A69,"") -> C0010 | T27: =IF(pivots!B69<>0,pivots!B69,"") -> 900 | U27: =IF(pivots!C69<>0,pivots!C69,"") -> 1470 | V27: =IF(pivots!D69<>0,pivots!D69,"") -> 1617 | W27: =IF(pivots!E69<>0,pivots!E69,"") -> 1314 | X27: =IF(pivots!F69<>0,pivots!F69,"") -> 941 | Y27: =IF(pivots!G69<>0,pivots!G69,"") -> 6242
S28: =IF(pivots!A70<>0,pivots!A70,"") -> C0013 | T28: =IF(pivots!B70<>0,pivots!B70,"") -> 1255 | U28: =IF(pivots!C70<>0,pivots!C70,"") -> 516 | V28: =IF(pivots!D70<>0,pivots!D70,"") -> 1874 | W28: =IF(pivots!E70<>0,pivots!E70,"") -> 1863 | X28: =IF(pivots!F70<>0,pivots!F70,"") -> 1722 | Y28: =IF(pivots!G70<>0,pivots!G70,"") -> 7230
S29: =IF(pivots!A71<>0,pivots!A71,"") -> C0015 | T29: =IF(pivots!B71<>0,pivots!B71,"") -> 1138 | U29: =IF(pivots!C71<>0,pivots!C71,"") -> 1898 | V29: =IF(pivots!D71<>0,pivots!D71,"") -> 1482 | W29: =IF(pivots!E71<>0,pivots!E71,"") -> 846 | X29: =IF(pivots!F71<>0,pivots!F71,"") -> 1154 | Y29: =IF(pivots!G71<>0,pivots!G71,"") -> 6518
... S36: =IF(pivots!A78<>0,pivots!A78,"") -> Grand Total | T36: =IF(pivots!B78<>0,pivots!B78,"") -> 18415 | U36: =IF(pivots!C78<>0,pivots!C78,"") -> 20581 | V36: =IF(pivots!D78<>0,pivots!D78,"") -> 20872 | W36: =IF(pivots!E78<>0,pivots!E78,"") -> 16651 | X36: =IF(pivots!F78<>0,pivots!F78,"") -> 20104 | Y36: =IF(pivots!G78<>0,pivots!G78,"") -> 96623

Sheet pivots
A3: Call_count | B3: Total_amount | C3: Duration_count | D3: Avg.rat | E3: 5*calls | F3: amt_per_call
A4: 1000 | B4: 96623 | C4: 89850 | D4: 3.964 | E4: 307 | F4: 96.623
A9: Call_count | B9: Total_amount | C9: Duration_count | D9: Avg.rat | E9: 5*calls | F9: amt_per_call
A10: 1000 | B10: 96623 | C10: 89850 | D10: 3.964 | E10: 307 | F10: 96.623
A15: Row Labels | B15: Count of Customer ID | C15: Call_count | E15: Row Labels | F15: Call_count
A16: Jan | B16: 79 | C16: 79 | E16: Sunday | F16: 146
A17: Feb | B17: 66 | C17: 66 | E17: Saturday | F17: 161
A18: Mar | B18: 155 | C18: 155 | E18: Friday | F18: 141
A19: Apr | B19: 136 | C19: 136 | E19: Thursday | F19: 128
A20: May | B20: 83 | C20: 83 | E20: Wednesday | F20: 153
A21: Jun | B21: 67 | C21: 67 | E21: Tuesday | F21: 138
A22: Jul | B22: 64 | C22: 64 | E22: Monday | F22: 133
A23: Aug | B23: 50 | C23: 50 | E23: Grand Total | F23: 1000
A24: Sep | B24: 76 | C24: 76
A25: Oct | B25: 114 | C25: 114
A26: Nov | B26: 57 | C26: 57 | E26: Row Labels | F26: Count of Customer ID
A27: Dec | B27: 53 | C27: 53 | E27: 0 | F27: 1
A28: Grand Total | B28: 1000 | C28: 1000 | E28: 1 | F28: 8
E29: 2 | F29: 59
E30: 3 | F30: 197
E31: 4 | F31: 428
E32: 5 | F32: 307
A33: Count of Call number | B33: Column Labels | E33: Grand Total | F33: 1000
A34: Row Labels | B34: Female | C34: Male | D34: Grand Total
A35: Cincinnati | B35: 144 | C35: 132 | D35: 276
A36: Cleveland | B36: 326 | C36: 63 | D36: 389
A37: Columbus | B37: 129 | C37: 206 | D37: 335
A38: Grand Total | B38: 599 | C38: 401 | D38: 1000
E41: default rep | H41: Selected rep
A42: Row Labels | B42: Call_count | C42: Total_amount | H42: =A50 -> R01
A43: R01 | B43: 189 | C43: 18415 | E43: =A43 -> R01 | F43: =B43 -> 189 | G43: =C43 -> 18415 | H43: =IF($H$42=$E43,F43,"") -> 189 | I43: =IF($H$42=$E43,G43,"") -> 18415
A44: R02 | B44: 218 | C44: 20581 | E44: =A44 -> R02 | F44: =B44 -> 218 | G44: =C44 -> 20581 | H44: =IF($H$42=$E44,F44,"") | I44: =IF($H$42=$E44,G44,"")
A45: R03 | B45: 207 | C45: 20872 | E45: =A45 -> R03 | F45: =B45 -> 207 | G45: =C45 -> 20872 | H45: =IF($H$42=$E45,F45,"") | I45: =IF($H$42=$E45,G45,"")
A46: R04 | B46: 186 | C46: 16651 | E46: =A46 -> R04 | F46: =B46 -> 186 | G46: =C46 -> 16651 | H46: =IF($H$42=$E46,F46,"") | I46: =IF($H$42=$E46,G46,"")
A47: R05 | B47: 200 | C47: 20104 | E47: =A47 -> R05 | F47: =B47 -> 200 | G47: =C47 -> 20104 | H47: =IF($H$42=$E47,F47,"") | I47: =IF($H$42=$E47,G47,"")
A49: Row Labels
A50: R01
A51: R02
A52: R03
A53: R04
...

Sheet Data
B1: Call Centre Data
B3: Call number | C3: Customer ID | D3: Duration | E3: Representative | F3: Date of Call | G3: Purchase Amount | H3: Satisfaction Rating | I3: Financial Year | J3: Day of week | K3: Duration Bucket | L3: Rating rounded | Q3: Customer ID | R3: Gedner | S3: Age | T3: City
B4: Call_7271 | C4: C0003 | D4: 116 | E4: R05 | F4: 44927 | G4: 128 | H4: 4.9 | I4: =IF(MONTH(calls[[#This Row],[Date of Call]])<=6, YEAR(calls[[#This Row],[Date of Call]]), YEAR(calls[[#This Row],[Date of Call]])+1) -> 2023 | J4: =TEXT(calls[[#This Row],[Date of Call]],"DDDD") -> Sunday | K4: {=_xlfn.IFS(calls[[#This Row],[Duration]]<=10,"Under 10 mins", calls[[#This Row],[Duration]]<=30, "10 to 30 mins", calls[[#This Row],[Duration]]<=60, "30 to 60 mins", calls[[#This Row],[Duration]]<=120, "1 to 2 hours", TRUE, "More than 2 hours")} -> 1 to 2 hours | L4: =ROUND(calls[[#This Row],[Satisfaction Rating]],0) -> 5 | Q4: C0001 | R4: Male | S4: 41 | T4: Columbus
B5: Call_7272 | C5: C0004 | D5: 119 | E5: R05 | F5: 44927 | G5: 135 | H5: 2.9 | I5: =IF(MONTH(calls[[#This Row],[Date of Call]])<=6, YEAR(calls[[#This Row],[Date of Call]]), YEAR(calls[[#This Row],[Date of Call]])+1) -> 2023 | J5: =TEXT(calls[[#This Row],[Date of Call]],"DDDD") -> Sunday | K5: {=_xlfn.IFS(calls[[#This Row],[Duration]]<=10,"Under 10 mins", calls[[#This Row],[Duration]]<=30, "10 to 30 mins", calls[[#This Row],[Duration]]<=60, "30 to 60 mins", calls[[#This Row],[Duration]]<=120, "1 to 2 hours", TRUE, "More than 2 hours")} -> 1 to 2 hours | L5: =ROUND(calls[[#This Row],[Satisfaction Rating]],0) -> 3 | Q5: C0002 | R5: Male | S5: 31 | T5: Cleveland
B6: Call_7273 | C6: C0005 | D6: 68 | E6: R02 | F6: 44927 | G6: 66 | H6: 4.7 | I6: =IF(MONTH(calls[[#This Row],[Date of Call]])<=6, YEAR(calls[[#This Row],[Date of Call]]), YEAR(calls[[#This Row],[Date of Call]])+1) -> 2023 | J6: =TEXT(calls[[#This Row],[Date of Call]],"DDDD") -> Sunday | K6: {=_xlfn.IFS(calls[[#This Row],[Duration]]<=10,"Under 10 mins", calls[[#This Row],[Duration]]<=30, "10 to 30 mins", calls[[#This Row],[Duration]]<=60, "30 to 60 mins", calls[[#This Row],[Duration]]<=120, "1 to 2 hours", TRUE, "More than 2 hours")} -> 1 to 2 hours | L6: =ROUND(calls[[#This Row],[Satisfaction Rating]],0) -> 5 | Q6: C0003 | R6: Male | S6: 26 | T6: Cincinnati
B7: Call_7274 | C7: C0014 | D7: 119 | E7: R02 | F7: 44927 | G7: 22 | H7: 2.9 | I7: =IF(MONTH(calls[[#This Row],[Date of Call]])<=6, YEAR(calls[[#This Row],[Date of Call]]), YEAR(calls[[#This Row],[Date of Call]])+1) -> 2023 | J7: =TEXT(calls[[#This Row],[Date of Call]],"DDDD") -> Sunday | K7: {=_xlfn.IFS(calls[[#This Row],[Duration]]<=10,"Under 10 mins", calls[[#This Row],[Duration]]<=30, "10 to 30 mins", calls[[#This Row],[Duration]]<=60, "30 to 60 mins", calls[[#This Row],[Duration]]<=120, "1 to 2 hours", TRUE, "More than 2 hours")} -> 1 to 2 hours | L7: =ROUND(calls[[#This Row],[Satisfaction Rating]],0) -> 3 | Q7: C0004 | R7: Male | S7: 36 | T7: Cincinnati
B8: Call_7275 | C8: C0011 | D8: 128 | E8: R01 | F8: 44928 | G8: 31 | H8: 2.8 | I8: =IF(MONTH(calls[[#This Row],[Date of Call]])<=6, YEAR(calls[[#This Row],[Date of Call]]), YEAR(calls[[#This Row],[Date of Call]])+1) -> 2023 | J8: =TEXT(calls[[#This Row],[Date of Call]],"DDDD") -> Monday | K8: {=_xlfn.IFS(calls[[#This Row],[Duration]]<=10,"Under 10 mins", calls[[#This Row],[Duration]]<=30, "10 to 30 mins", calls[[#This Row],[Duration]]<=60, "30 to 60 mins", calls[[#This Row],[Duration]]<=120, "1 to 2 hours", TRUE, "More than 2 hours")} -> More than 2 hours | L8: =ROUND(calls[[#This Row],[Satisfaction Rating]],0) -> 3 | Q8: C0005 | R8: Male | S8: 37 | T8: Columbus
B9: Call_7276 | C9: C0011 | D9: 49 | E9: R02 | F9: 44929 | G9: 135 | H9: 4.8 | I9: =IF(MONTH(calls[[#This Row],[Date of Call]])<=6, YEAR(calls[[#This Row],[Date of Call]]), YEAR(calls[[#This Row],[Date of Call]])+1) -> 2023 | J9: =TEXT(calls[[#This Row],[Date of Call]],"DDDD") -> Tuesday | K9: {=_xlfn.IFS(calls[[#This Row],[Duration]]<=10,"Under 10 mins", calls[[#This Row],[Duration]]<=30, "10 to 30 mins", calls[[#This Row],[Duration]]<=60, "30 to 60 mins", calls[[#This Row],[Duration]]<=120, "1 to 2 hours", TRUE, "More than 2 hours")} -> 30 to 60 mins | L9: =ROUND(calls[[#This Row],[Satisfaction Rating]],0) -> 5 | Q9: C0006 | R9: Male | S9: 23 | T9: Columbus
B10: Call_7277 | C10: C0007 | D10: 84 | E10: R05 | F10: 44929 | G10: 60 | H10: 4.7 | I10: =IF(MONTH(calls[[#This Row],[Date of Call]])<=6, YEAR(calls[[#This Row],[Date of Call]]), YEAR(calls[[#This Row],[Date of Call]])+1) -> 2023 | J10: =TEXT(calls[[#This Row],[Date of Call]],"DDDD") -> Tuesday | K10: {=_xlfn.IFS(calls[[#This Row],[Duration]]<=10,"Under 10 mins", calls[[#This Row],[Duration]]<=30, "10 to 30 mins", calls[[#This Row],[Duration]]<=60, "30 to 60 mins", calls[[#This Row],[Duration]]<=120, "1 to 2 hours", TRUE, "More than 2 hours")} -> 1 to 2 hours | L10: =ROUND(calls[[#This Row],[Satisfaction Rating]],0) -> 5 | Q10: C0007 | R10: Female | S10: 22 | T10: Cleveland
B11: Call_7278 | C11: C0003 | D11: 103 | E11: R04 | F11: 44929 | G11: 148 | H11: 4.4 | I11: =IF(MONTH(calls[[#This Row],[Date of Call]])<=6, YEAR(calls[[#This Row],[Date of Call]]), YEAR(calls[[#This Row],[Date of Call]])+1) -> 2023 | J11: =TEXT(calls[[#This Row],[Date of Call]],"DDDD") -> Tuesday | K11: {=_xlfn.IFS(calls[[#This Row],[Duration]]<=10,"Under 10 mins", calls[[#This Row],[Duration]]<=30, "10 to 30 mins", calls[[#This Row],[Duration]]<=60, "30 to 60 mins", calls[[#This Row],[Duration]]<=120, "1 to 2 hours", TRUE, "More than 2 hours")} -> 1 to 2 hours | L11: =ROUND(calls[[#This Row],[Satisfaction Rating]],0) -> 4 | Q11: C0008 | R11: Female | S11: 42 | T11: Cleveland
B12: Call_7279 | C12: C0005 | D12: 31 | E12: R02 | F12: 44929 | G12: 135 | H12: 3.6 | I12: =IF(MONTH(calls[[#This Row],[Date of Call]])<=6, YEAR(calls[[#This Row],[Date of Call]]), YEAR(calls[[#This Row],[Date of Call]])+1) -> 2023 | J12: =TEXT(calls[[#This Row],[Date of Call]],"DDDD") -> Tuesday | K12: {=_xlfn.IFS(calls[[#This Row],[Duration]]<=10,"Under 10 mins", calls[[#This Row],[Duration]]<=30, "10 to 30 mins", calls[[#This Row],[Duration]]<=60, "30 to 60 mins", calls[[#This Row],[Duration]]<=120, "1 to 2 hours", TRUE, "More than 2 hours")} -> 30 to 60 mins | L12: =ROUND(calls[[#This Row],[Satisfaction Rating]],0) -> 4 | Q12: C0009 | R12: Female | S12: 25 | T12: Columbus
B13: Call_7280 | C13: C0010 | D13: 44 | E13: R03 | F13: 44929 | G13: 105 | H13: 2.9 | I13: =IF(MONTH(calls[[#This Row],[Date of Call]])<=6, YEAR(calls[[#This Row],[Date of Call]]), YEAR(calls[[#This Row],[Date of Call]])+1) -> 2023 | J13: =TEXT(calls[[#This Row],[Date of Call]],"DDDD") -> Tuesday | K13: {=_xlfn.IFS(calls[[#This Row],[Duration]]<=10,"Under 10 mins", calls[[#This Row],[Duration]]<=30, "10 to 30 mins", calls[[#This Row],[Duration]]<=60, "30 to 60 mins", calls[[#This Row],[Duration]]<=120, "1 to 2 hours", TRUE, "More than 2 hours")} -> 30 to 60 mins | L13: =ROUND(calls[[#This Row],[Satisfaction Rating]],0) -> 3 | Q13: C0010 | R13: Female | S13: 30 | T13: Cleveland
B14: Call_7281 | C14: C0011 | D14: 102 | E14: R02 | F14: 44929 | G14: 69 | H14: 4.9 | I14: =IF(MONTH(calls[[#This Row],[Date of Call]])<=6, YEAR(calls[[#This Row],[Date of Call]]), YEAR(calls[[#This Row],[Date of Call]])+1) -> 2023 | J14: =TEXT(calls[[#This Row],[Date of Call]],"DDDD") -> Tuesday | K14: {=_xlfn.IFS(calls[[#This Row],[Duration]]<=10,"Under 10 mins", calls[[#This Row],[Duration]]<=30, "10 to 30 mins", calls[[#This Row],[Duration]]<=60, "30 to 60 mins", calls[[#This Row],[Duration]]<=120, "1 to 2 hours", TRUE, "More than 2 hours")} -> 1 to 2 hours | L14: =ROUND(calls[[#This Row],[Satisfaction Rating]],0) -> 5 | Q14: C0011 | R14: Female | S14: 30 | T14: Cincinnati
B15: Call_7282 | C15: C0013 | D15: 135 | E15: R05 | F15: 44929 | G15: 46 | H15: 3.4 | I15: =IF(MONTH(calls[[#This Row],[Date of Call]])<=6, YEAR(calls[[#This Row],[Date of Call]]), YEAR(calls[[#This Row],[Date of Call]])+1) -> 2023 | J15: =TEXT(calls[[#This Row],[Date of Call]],"DDDD") -> Tuesday | K15: {=_xlfn.IFS(calls[[#This Row],[Duration]]<=10,"Under 10 mins", calls[[#This Row],[Duration]]<=30, "10 to 30 mins", calls[[#This Row],[Duration]]<=60, "30 to 60 mins", calls[[#This Row],[Duration]]<=120, "1 to 2 hours", TRUE, "More than 2 hours")} -> More than 2 hours | L15: =ROUND(calls[[#This Row],[Satisfaction Rating]],0) -> 3 | Q15: C0012 | R15: Female | S15: 28 | T15: Cincinnati
... B18: Call_7285 | C18: C0013 | D18: 48 | E18: R01 | F18: 44930 | G18: 68 | H18: 4.9 | I18: =IF(MONTH(calls[[#This Row],[Date of Call]])<=6, YEAR(calls[[#This Row],[Date of Call]]), YEAR(calls[[#This Row],[Date of Call]])+1) -> 2023 | J18: =TEXT(calls[[#This Row],[Date of Call]],"DDDD") -> Wednesday | K18: {=_xlfn.IFS(calls[[#This Row],[Duration]]<=10,"Under 10 mins", calls[[#This Row],[Duration]]<=30, "10 to 30 mins", calls[[#This Row],[Duration]]<=60, "30 to 60 mins", calls[[#This Row],[Duration]]<=120, "1 to 2 hours", TRUE, "More than 2 hours")} -> 30 to 60 mins | L18: =ROUND(calls[[#This Row],[Satisfaction Rating]],0) -> 5 | Q18: C0015 | R18: Female | S18: 43 | T18: Cleveland
B19: Call_7286 | C19: C0010 | D19: 176 | E19: R05 | F19: 44931 | G19: 24 | H19: 4.8 | I19: =IF(MONTH(calls[[#This Row],[Date of Call]])<=6, YEAR(calls[[#This Row],[Date of Call]]), YEAR(calls[[#This Row],[Date of Call]])+1) -> 2023 | J19: =TEXT(calls[[#This Row],[Date of Call]],"DDDD") -> Thursday | K19: {=_xlfn.IFS(calls[[#This Row],[Duration]]<=10,"Under 10 mins", calls[[#This Row],[Duration]]<=30, "10 to 30 mins", calls[[#This Row],[Duration]]<=60, "30 to 60 mins", calls[[#This Row],[Duration]]<=120, "1 to 2 hours", TRUE, "More than 2 hours")} -> More than 2 hours | L19: =ROUND(calls[[#This Row],[Satisfaction Rating]],0) -> 5
B20: Call_7287 | C20: C0010 | D20: 99 | E20: R01 | F20: 44931 | G20: 195 | H20: 3.9 | I20: =IF(MONTH(calls[[#This Row],[Date of Call]])<=6, YEAR(calls[[#This Row],[Date of Call]]), YEAR(calls[[#This Row],[Date of Call]])+1) -> 2023 | J20: =TEXT(calls[[#This Row],[Date of Call]],"DDDD") -> Thursday | K20: {=_xlfn.IFS(calls[[#This Row],[Duration]]<=10,"Under 10 mins", calls[[#This Row],[Duration]]<=30, "10 to 30 mins", calls[[#This Row],[Duration]]<=60, "30 to 60 mins", calls[[#This Row],[Duration]]<=120, "1 to 2 hours", TRUE, "More than 2 hours")} -> 1 to 2 hours | L20: =ROUND(calls[[#This Row],[Satisfaction Rating]],0) -> 4
B21: Call_7288 | C21: C0009 | D21: 28 | E21: R03 | F21: 44931 | G21: 28 | H21: 3.8 | I21: =IF(MONTH(calls[[#This Row],[Date of Call]])<=6, YEAR(calls[[#This Row],[Date of Call]]), YEAR(calls[[#This Row],[Date of Call]])+1) -> 2023 | J21: =TEXT(calls[[#This Row],[Date of Call]],"DDDD") -> Thursday | K21: {=_xlfn.IFS(calls[[#This Row],[Duration]]<=10,"Under 10 mins", calls[[#This Row],[Duration]]<=30, "10 to 30 mins", calls[[#This Row],[Duration]]<=60, "30 to 60 mins", calls[[#This Row],[Duration]]<=120, "1 to 2 hours", TRUE, "More than 2 hours")} -> 10 to 30 mins | L21: =ROUND(calls[[#This Row],[Satisfaction Rating]],0) -> 4
B22: Call_7289 | C22: C0007 | D22: 54 | E22: R02 | F22: 44931 | G22: 170 | H22: 4.3 | I22: =IF(MONTH(calls[[#This Row],[Date of Call]])<=6, YEAR(calls[[#This Row],[Date of Call]]), YEAR(calls[[#This Row],[Date of Call]])+1) -> 2023 | J22: =TEXT(calls[[#This Row],[Date of Call]],"DDDD") -> Thursday | K22: {=_xlfn.IFS(calls[[#This Row],[Duration]]<=10,"Under 10 mins", calls[[#This Row],[Duration]]<=30, "10 to 30 mins", calls[[#This Row],[Duration]]<=60, "30 to 60 mins", calls[[#This Row],[Duration]]<=120, "1 to 2 hours", TRUE, "More than 2 hours")} -> 30 to 60 mins | L22: =ROUND(calls[[#This Row],[Satisfaction Rating]],0) -> 4
B23: Call_7290 | C23: C0006 | D23: 48 | E23: R05 | F23: 44932 | G23: 30 | H23: 4.4 | I23: =IF(MONTH(calls[[#This Row],[Date of Call]])<=6, YEAR(calls[[#This Row],[Date of Call]]), YEAR(calls[[#This Row],[Date of Call]])+1) -> 2023 | J23: =TEXT(calls[[#This Row],[Date of Call]],"DDDD") -> Friday | K23: {=_xlfn.IFS(calls[[#This Row],[Duration]]<=10,"Under 10 mins", calls[[#This Row],[Duration]]<=30, "10 to 30 mins", calls[[#This Row],[Duration]]<=60, "30 to 60 mins", calls[[#This Row],[Duration]]<=120, "1 to 2 hours", TRUE, "More than 2 hours")} -> 30 to 60 mins | L23: =ROUND(calls[[#This Row],[Satisfaction Rating]],0) -> 4
B24: Call_7291 | C24: C0004 | D24: 128 | E24: R05 | F24: 44932 | G24: 72 | H24: 5 | I24: =IF(MONTH(calls[[#This Row],[Date of Call]])<=6, YEAR(calls[[#This Row],[Date of Call]]), YEAR(calls[[#This Row],[Date of Call]])+1) -> 2023 | J24: =TEXT(calls[[#This Row],[Date of Call]],"DDDD") -> Friday | K24: {=_xlfn.IFS(calls[[#This Row],[Duration]]<=10,"Under 10 mins", calls[[#This Row],[Duration]]<=30, "10 to 30 mins", calls[[#This Row],[Duration]]<=60, "30 to 60 mins", calls[[#This Row],[Duration]]<=120, "1 to 2 hours", TRUE, "More than 2 hours")} -> More than 2 hours | L24: =ROUND(calls[[#This Row],[Satisfaction Rating]],0) -> 5
B25: Call_7292 | C25: C0004 | D25: 38 | E25: R04 | F25: 44933 | G25: 92 | H25: 4.9 | I25: =IF(MONTH(calls[[#This Row],[Date of Call]])<=6, YEAR(calls[[#This Row],[Date of Call]]), YEAR(calls[[#This Row],[Date of Call]])+1) -> 2023 | J25: =TEXT(calls[[#This Row],[Date of Call]],"DDDD") -> Saturday | K25: {=_xlfn.IFS(calls[[#This Row],[Duration]]<=10,"Under 10 mins", calls[[#This Row],[Duration]]<=30, "10 to 30 mins", calls[[#This Row],[Duration]]<=60, "30 to 60 mins", calls[[#This Row],[Duration]]<=120, "1 to 2 hours", TRUE, "More than 2 hours")} -> 30 to 60 mins | L25: =ROUND(calls[[#This Row],[Satisfaction Rating]],0) -> 5
B26: Call_7293 | C26: C0003 | D26: 67 | E26: R04 | F26: 44934 | G26: 165 | H26: 4.5 | I26: =IF(MONTH(calls[[#This Row],[Date of Call]])<=6, YEAR(calls[[#This Row],[Date of Call]]), YEAR(calls[[#This Row],[Date of Call]])+1) -> 2023 | J26: =TEXT(calls[[#This Row],[Date of Call]],"DDDD") -> Sunday | K26: {=_xlfn.IFS(calls[[#This Row],[Duration]]<=10,"Under 10 mins", calls[[#This Row],[Duration]]<=30, "10 to 30 mins", calls[[#This Row],[Duration]]<=60, "30 to 60 mins", calls[[#This Row],[Duration]]<=120, "1 to 2 hours", TRUE, "More than 2 hours")} -> 1 to 2 hours | L26: =ROUND(calls[[#This Row],[Satisfaction Rating]],0) -> 5
B27: Call_7294 | C27: C0015 | D27: 58 | E27: R02 | F27: 44934 | G27: 140 | H27: 2.1 | I27: =IF(MONTH(calls[[#This Row],[Date of Call]])<=6, YEAR(calls[[#This Row],[Date of Call]]), YEAR(calls[[#This Row],[Date of Call]])+1) -> 2023 | J27: =TEXT(calls[[#This Row],[Date of Call]],"DDDD") -> Sunday | K27: {=_xlfn.IFS(calls[[#This Row],[Duration]]<=10,"Under 10 mins", calls[[#This Row],[Duration]]<=30, "10 to 30 mins", calls[[#This Row],[Duration]]<=60, "30 to 60 mins", calls[[#This Row],[Duration]]<=120, "1 to 2 hours", TRUE, "More than 2 hours")} -> 30 to 60 mins | L27: =ROUND(calls[[#This Row],[Satisfaction Rating]],0) -> 2
B28: Call_7295 | C28: C0010 | D28: 54 | E28: R01 | F28: 44934 | G28: 111 | H28: 3.3 | I28: =IF(MONTH(calls[[#This Row],[Date of Call]])<=6, YEAR(calls[[#This Row],[Date of Call]]), YEAR(calls[[#This Row],[Date of Call]])+1) -> 2023 | J28: =TEXT(calls[[#This Row],[Date of Call]],"DDDD") -> Sunday | K28: {=_xlfn.IFS(calls[[#This Row],[Duration]]<=10,"Under 10 mins", calls[[#This Row],[Duration]]<=30, "10 to 30 mins", calls[[#This Row],[Duration]]<=60, "30 to 60 mins", calls[[#This Row],[Duration]]<=120, "1 to 2 hours", TRUE, "More than 2 hours")} -> 30 to 60 mins | L28: =ROUND(calls[[#This Row],[Satisfaction Rating]],0) -> 3
B29: Call_7296 | C29: C0012 | D29: 28 | E29: R05 | F29: 44935 | G29: 63 | H29: 4.1 | I29: =IF(MONTH(calls[[#This Row],[Date of Call]])<=6, YEAR(calls[[#This Row],[Date of Call]]), YEAR(calls[[#This Row],[Date of Call]])+1) -> 2023 | J29: =TEXT(calls[[#This Row],[Date of Call]],"DDDD") -> Monday | K29: {=_xlfn.IFS(calls[[#This Row],[Duration]]<=10,"Under 10 mins", calls[[#This Row],[Duration]]<=30, "10 to 30 mins", calls[[#This Row],[Duration]]<=60, "30 to 60 mins", calls[[#This Row],[Duration]]<=120, "1 to 2 hours", TRUE, "More than 2 hours")} -> 10 to 30 mins | L29: =ROUND(calls[[#This Row],[Satisfaction Rating]],0) -> 4
B30: Call_7297 | C30: C0002 | D30: 73 | E30: R05 | F30: 44935 | G30: 80 | H30: 4.2 | I30: =IF(MONTH(calls[[#This Row],[Date of Call]])<=6, YEAR(calls[[#This Row],[Date of Call]]), YEAR(calls[[#This Row],[Date of Call]])+1) -> 2023 | J30: =TEXT(calls[[#This Row],[Date of Call]],"DDDD") -> Monday | K30: {=_xlfn.IFS(calls[[#This Row],[Duration]]<=10,"Under 10 mins", calls[[#This Row],[Duration]]<=30, "10 to 30 mins", calls[[#This Row],[Duration]]<=60, "30 to 60 mins", calls[[#This Row],[Duration]]<=120, "1 to 2 hours", TRUE, "More than 2 hours")} -> 1 to 2 hours | L30: =ROUND(calls[[#This Row],[Satisfaction Rating]],0) -> 4
... B1003: Call_8270 | C1003: C0009 | D1003: 114 | E1003: R01 | F1003: 45291 | G1003: 40 | H1003: 3.9 | I1003: =IF(MONTH(calls[[#This Row],[Date of Call]])<=6, YEAR(calls[[#This Row],[Date of Call]]), YEAR(calls[[#This Row],[Date of Call]])+1) -> 2024 | J1003: =TEXT(calls[[#This Row],[Date of Call]],"DDDD") -> Sunday | K1003: {=_xlfn.IFS(calls[[#This Row],[Duration]]<=10,"Under 10 mins", calls[[#This Row],[Duration]]<=30, "10 to 30 mins", calls[[#This Row],[Duration]]<=60, "30 to 60 mins", calls[[#This Row],[Duration]]<=120, "1 to 2 hours", TRUE, "More than 2 hours")} -> 1 to 2 hours | L1003: =ROUND(calls[[#This Row],[Satisfaction Rating]],0) -> 4

Sheet Assets
